<?xml version="1.0" encoding="utf-8"?>
<!-- This URDF was automatically created by SolidWorks to URDF Exporter! Originally created by Stephen Brawner (brawner@gmail.com) 
     Commit Version: 1.6.0-4-g7f85cfe  Build Version: 1.6.7995.38578
     For more information, please see http://wiki.ros.org/sw_urdf_exporter -->
<robot
  name="robot_arm_urdf2">
  <link
    name="base_link">
    <inertial>
      <origin
        xyz="0.00098773 0.00036668 0.026759"
        rpy="0 0 0" />
      <mass
        value="0.09553" />
      <inertia
        ixx="4.2897E-05"
        ixy="-2.011E-08"
        ixz="-3.3533E-07"
        iyy="8.7515E-05"
        iyz="4.8236E-09"
        izz="0.00011674" />
    </inertial>
    <visual>
      <origin
        xyz="0 0 0"
        rpy="0 0 0" />
      <geometry>
        <mesh
          filename="package://robot_arm_urdf2/meshes/base_link.STL" />
      </geometry>
      <material
        name="">
        <color
          rgba="0.79216 0.81961 0.93333 1" />
      </material>
    </visual>
    <collision>
      <origin
        xyz="0 0 0"
        rpy="0 0 0" />
      <geometry>
        <mesh
          filename="package://robot_arm_urdf2/meshes/base_link.STL" />
      </geometry>
    </collision>
  </link>
  <link
    name="Link_2">
    <inertial>
      <origin
        xyz="0.010261 0.00032954 0.054832"
        rpy="0 0 0" />
      <mass
        value="0.009426" />
      <inertia
        ixx="3.9911E-06"
        ixy="-1.7068E-10"
        ixz="-4.2478E-07"
        iyy="5.4466E-06"
        iyz="-1.3984E-08"
        izz="1.6595E-06" />
    </inertial>
    <visual>
      <origin
        xyz="0 0 0"
        rpy="0 0 0" />
      <geometry>
        <mesh
          filename="package://robot_arm_urdf2/meshes/Link_2.STL" />
      </geometry>
      <material
        name="">
        <color
          rgba="0.79216 0.81961 0.93333 1" />
      </material>
    </visual>
    <collision>
      <origin
        xyz="0 0 0"
        rpy="0 0 0" />
      <geometry>
        <mesh
          filename="package://robot_arm_urdf2/meshes/Link_2.STL" />
      </geometry>
    </collision>
  </link>
  <joint
    name="joint_2"
    type="revolute">
    <origin
      xyz="0.011 -0.0125 0.074"
      rpy="0 0 0" />
    <parent
      link="base_link" />
    <child
      link="Link_2" />
    <axis
      xyz="0 1 0" />
    <limit
      lower="3.48"
      upper="3.142"
      effort="300"
      velocity="3" />
  </joint>
  <link
    name="Link_3">
    <inertial>
      <origin
        xyz="0.083282 -0.01623 0.024264"
        rpy="0 0 0" />
      <mass
        value="0.015764" />
      <inertia
        ixx="1.3569E-06"
        ixy="4.4614E-10"
        ixz="-2.8646E-07"
        iyy="1.357E-06"
        iyz="-9.9912E-10"
        izz="1.8908E-06" />
    </inertial>
    <visual>
      <origin
        xyz="0 0 0"
        rpy="0 0 0" />
      <geometry>
        <mesh
          filename="package://robot_arm_urdf2/meshes/Link_3.STL" />
      </geometry>
      <material
        name="">
        <color
          rgba="0.79216 0.81961 0.93333 1" />
      </material>
    </visual>
    <collision>
      <origin
        xyz="0 0 0"
        rpy="0 0 0" />
      <geometry>
        <mesh
          filename="package://robot_arm_urdf2/meshes/Link_3.STL" />
      </geometry>
    </collision>
  </link>
  <joint
    name="joint_3"
    type="revolute">
    <origin
      xyz="0.00091242 0.0235 0.076995"
      rpy="0 0 0" />
    <parent
      link="Link_2" />
    <child
      link="Link_3" />
    <axis
      xyz="0 -1 0" />
    <limit
      lower="0"
      upper="0"
      effort="0"
      velocity="0" />
  </joint>
  <link
    name="Link_4">
    <inertial>
      <origin
        xyz="0.097771 -0.0066902 0.16372"
        rpy="0 0 0" />
      <mass
        value="0.011801" />
      <inertia
        ixx="1.8122E-06"
        ixy="-4.669E-08"
        ixz="-6.0989E-07"
        iyy="1.7021E-06"
        iyz="-2.0848E-08"
        izz="2.9057E-06" />
    </inertial>
    <visual>
      <origin
        xyz="0 0 0"
        rpy="0 0 0" />
      <geometry>
        <mesh
          filename="package://robot_arm_urdf2/meshes/Link_4.STL" />
      </geometry>
      <material
        name="">
        <color
          rgba="0.79216 0.81961 0.93333 1" />
      </material>
    </visual>
    <collision>
      <origin
        xyz="0 0 0"
        rpy="0 0 0" />
      <geometry>
        <mesh
          filename="package://robot_arm_urdf2/meshes/Link_4.STL" />
      </geometry>
    </collision>
  </link>
  <joint
    name="joint_4"
    type="revolute">
    <origin
      xyz="-0.011912 -0.011 -0.15099"
      rpy="0 0 0" />
    <parent
      link="Link_3" />
    <child
      link="Link_4" />
    <axis
      xyz="0 0 1" />
    <limit
      lower="0.87"
      upper="1.571"
      effort="300"
      velocity="3" />
  </joint>
  <link
    name="Link_5">
    <inertial>
      <origin
        xyz="0.00011656 -0.0031438 0.03813"
        rpy="0 0 0" />
      <mass
        value="0.0098791" />
      <inertia
        ixx="2.9408E-06"
        ixy="1.2652E-11"
        ixz="-9.9219E-07"
        iyy="6.6353E-06"
        iyz="1.0676E-09"
        izz="3.709E-06" />
    </inertial>
    <visual>
      <origin
        xyz="0 0 0"
        rpy="0 0 0" />
      <geometry>
        <mesh
          filename="package://robot_arm_urdf2/meshes/Link_5.STL" />
      </geometry>
      <material
        name="">
        <color
          rgba="0.79216 0.81961 0.93333 1" />
      </material>
    </visual>
    <collision>
      <origin
        xyz="0 0 0"
        rpy="0 0 0" />
      <geometry>
        <mesh
          filename="package://robot_arm_urdf2/meshes/Link_5.STL" />
      </geometry>
    </collision>
  </link>
  <joint
    name="joint_5"
    type="revolute">
    <origin
      xyz="0.011 0.014 0.074"
      rpy="0 0 0" />
    <parent
      link="base_link" />
    <child
      link="Link_5" />
    <axis
      xyz="0 -1 0" />
    <limit
      lower="0"
      upper="1.65"
      effort="300"
      velocity="3" />
  </joint>
  <link
    name="Link_6">
    <inertial>
      <origin
        xyz="0.058512 0.0011651 0.0054999"
        rpy="0 0 0" />
      <mass
        value="0.0070977" />
      <inertia
        ixx="8.6666E-07"
        ixy="1.3043E-21"
        ixz="-2.1265E-07"
        iyy="3.254E-06"
        iyz="3.0712E-22"
        izz="2.3969E-06" />
    </inertial>
    <visual>
      <origin
        xyz="0 0 0"
        rpy="0 0 0" />
      <geometry>
        <mesh
          filename="package://robot_arm_urdf2/meshes/Link_6.STL" />
      </geometry>
      <material
        name="">
        <color
          rgba="0.79216 0.81961 0.93333 1" />
      </material>
    </visual>
    <collision>
      <origin
        xyz="0 0 0"
        rpy="0 0 0" />
      <geometry>
        <mesh
          filename="package://robot_arm_urdf2/meshes/Link_6.STL" />
      </geometry>
    </collision>
  </link>
  <joint
    name="joint_6"
    type="revolute">
    <origin
      xyz="-0.043546 -0.0245 0.15804"
      rpy="0 0 0" />
    <parent
      link="base_link" />
    <child
      link="Link_6" />
    <axis
      xyz="0 -1 0" />
    <limit
      lower="0"
      upper="3.142"
      effort="300"
      velocity="3" />
  </joint>
</robot>